Workbook
Name COMPLIANCE_CODE: '[1]Compliance Legend'!$C$5:$C$11
Name COMPLIANCE_LIST2: '[2]Compliance Code'!$C$5:$C$11

Sheet Cover Page
A2: =B9 -> Pengembangan Liveness | I2: Versi : | J2: 1.0
I3: Nomor
I4: Tanggal : | J4: 43797
B9: Pengembangan Liveness
B11: Evaluasi Proof of Concept
O19: 1.0
O20: Jakarta - November 2019

Sheet Note to Evaluators
B3: Catatan untuk Tim Evaluasi:
B4: Isilah cell yang berwarna kuning berdasarkan evaluasi / pengetahuan anda

Sheet Score Summary
A1: ='Cover Page'!B9 -> Pengembangan Liveness | C1: Versi : 1.0
C2: Nomor :
C3: Tanggal : 28 November 2019
A4: Nilai POC Keseluruhan
B6: Disiapkan Oleh | C6: Tanggal | D6: Tanda Tangan
B7: 1. Vebi Verdiana 2. Melie Rosita | D7: 1. 2.
B10: Diperiksa Oleh | C10: Tanggal | D10: Tanda Tangan
B11: 1. Ditto Prabowo Widigdo 2. Ignatius Adelbertus | D11: 1. 2.
C15: Nilai Bobot
B16: Pembobotan Evaluasi | C16: Vendor 1 | D16: Vendor 2 | E16: Vendor 3 | F16: Bobot
B17: Kuantitatif | C17: =SUMPRODUCT(C18:C31,$F$18:$F$31)/SUM($F$18:$F$31) -> #DIV/0! | D17: =SUMPRODUCT(D18:D31,$F$18:$F$31)/SUM($F$18:$F$31) -> #DIV/0! | E17: =SUMPRODUCT(E18:E31,$F$18:$F$31)/SUM($F$18:$F$31) -> #DIV/0! | F17: =SUM(F18:F31) -> 0.8
B19: Tracking | C19: =C45 -> #DIV/0! | D19: =C68 -> #DIV/0! | E19: =C91 -> #DIV/0! | F19: 0.3
B20: Additional Features | C20: =C46 -> #DIV/0! | D20: =C69 -> #DIV/0! | E20: =C92 -> #DIV/0! | F20: 0.1
B21: Reporting and Dashboard | C21: =C47 -> #DIV/0! | D21: =C70 -> #DIV/0! | E21: =C93 -> #DIV/0! | F21: 0.2
B22: IT Security, Intergration and Implementation | C22: =C48 -> #DIV/0! | D22: =C71 -> #DIV/0! | E22: =C94 -> #DIV/0! | F22: 0.1
B23: Support | C23: =C49 -> #DIV/0! | D23: =C72 -> #DIV/0! | E23: =C95 -> #DIV/0! | F23: 0.1
B32: Kualitatif | C32: =SUMPRODUCT(C33:C38,$F$33:$F$38)/SUM($F$33:$F$38) -> 0 | D32: =SUMPRODUCT(D33:D38,$F$33:$F$38)/SUM($F$33:$F$38) -> 0 | E32: =SUMPRODUCT(E33:E38,$F$33:$F$38)/SUM($F$33:$F$38) -> 0 | F32: =SUM(F33:F38) -> 0.2
B34: Tingkat Kesiapan | C34: =C60 -> 0 | D34: =C83 -> 0 | E34: =C106 -> 0 | F34: 0.05
B35: Profesionalitas Vendor | C35: =C61 -> 0 | D35: =C84 -> 0 | E35: =C107 -> 0 | F35: 0.05
B36: Nilai Tambah | C36: =C62 -> 0 | D36: =C85 -> 0 | E36: =C108 -> 0 | F36: 0.05
B37: Pemahaman Arsitektur | C37: =C63 -> 0 | D37: =C86 -> 0 | E37: =C109 -> 0 | F37: 0.025
B38: Pemahaman Infrastruktur | C38: =C64 -> 0 | D38: =C87 -> 0 | E38: =C110 -> 0 | F38: 0.025
B39: Total | C39: =SUMPRODUCT(C18:C31,$F$18:$F$31)+SUMPRODUCT(C33:C38,$F$33:$F$38) -> #DIV/0! | D39: =SUMPRODUCT(D18:D31,$F$18:$F$31)+SUMPRODUCT(D33:D38,$F$33:$F$38) -> #DIV/0! | E39: =SUMPRODUCT(E18:E31,$F$18:$F$31)+SUMPRODUCT(E33:E38,$F$33:$F$38) -> #DIV/0! | F39: =SUM(F17,F32) -> 1
C41: Vendor 1: Appsflyer Vendor 2: Adjust Vendor 3: Branch
B42: Nilai Mentah | C42: Vendor 1
B43: Kuantitatif
B45: Vendor Server | C45: =SUMIF('Quantitative Evaluation'!B:B,'Score Summary'!B45,'Quantitative Evaluation'!Q:Q)/SUMIF('Quantitative Evaluation'!B:B,'Score Summary'!B45,'Quantitative Evaluation'!E:E) -> #DIV/0!
B46: Vendor Application | C46: =SUMIF('Quantitative Evaluation'!B:B,'Score Summary'!B46,'Quantitative Evaluation'!Q:Q)/SUMIF('Quantitative Evaluation'!B:B,'Score Summary'!B46,'Quantitative Evaluation'!E:E) -> #DIV/0!
B47: Integrasi System dengan Bank | C47: =SUMIF('Quantitative Evaluation'!B:B,'Score Summary'!B47,'Quantitative Evaluation'!Q:Q)/SUMIF('Quantitative Evaluation'!B:B,'Score Summary'!B47,'Quantitative Evaluation'!E:E) -> #DIV/0!
B48: System Security | C48: =SUMIF('Quantitative Evaluation'!B:B,'Score Summary'!B48,'Quantitative Evaluation'!Q:Q)/SUMIF('Quantitative Evaluation'!B:B,'Score Summary'!B48,'Quantitative Evaluation'!E:E) -> #DIV/0!
B49: Other | C49: =SUMIF('Quantitative Evaluation'!B:B,'Score Summary'!B49,'Quantitative Evaluation'!Q:Q)/SUMIF('Quantitative Evaluation'!B:B,'Score Summary'!B49,'Quantitative Evaluation'!E:E) -> #DIV/0!
B58: Kualitatif
B60: Tingkat Kesiapan | C60: =SUMIF('Qualitative Eval'!B:B,'Score Summary'!$B60,'Qualitative Eval'!I:I)/SUMIF('Qualitative Eval'!B:B,'Score Summary'!$B60,'Qualitative Eval'!D:D) -> 0
B61: Profesionalitas Vendor | C61: =SUMIF('Qualitative Eval'!B:B,'Score Summary'!$B61,'Qualitative Eval'!I:I)/SUMIF('Qualitative Eval'!B:B,'Score Summary'!$B61,'Qualitative Eval'!D:D) -> 0
B62: Nilai Tambah | C62: =SUMIF('Qualitative Eval'!B:B,'Score Summary'!$B62,'Qualitative Eval'!I:I)/SUMIF('Qualitative Eval'!B:B,'Score Summary'!$B62,'Qualitative Eval'!D:D) -> 0
B63: Pemahaman Arsitektur | C63: =SUMIF('Qualitative Eval'!B:B,'Score Summary'!$B63,'Qualitative Eval'!I:I)/SUMIF('Qualitative Eval'!B:B,'Score Summary'!$B63,'Qualitative Eval'!D:D) -> 0
B64: Pemahaman Infrastruktur | C64: =SUMIF('Qualitative Eval'!B:B,'Score Summary'!$B64,'Qualitative Eval'!I:I)/SUMIF('Qualitative Eval'!B:B,'Score Summary'!$B64,'Qualitative Eval'!D:D) -> 0
B65: Nilai Mentah | C65: Vendor 2
B66: Kuantitatif
B68: Vendor Server | C68: =SUMIF('Quantitative Evaluation'!B:B,B68,'Quantitative Evaluation'!AC:AC)/SUMIF('Quantitative Evaluation'!B:B,B68,'Quantitative Evaluation'!E:E) -> #DIV/0!
...

Sheet Quantitative Evaluation
A1: ='Score Summary'!A1:B3 -> Pengembangan Liveness | D1: Versi : 1.0
D2: Nomor :
D3: Tanggal :
A4: Evaluasi Kuantitatif
A6: Vendor: | C6: Vendor 1: Appsflyer Vendor 2: Adjust Vendor 3: Branch
A7: Nama Evaluator: | C7: 1. 2.
A8: Tanda Tangan: | C8: 1. 2.
A10: Langkah | B10: Kategori Langkah | C10: Kegiatan | D10: Rincian | E10: Tingkat Kebutuhan | H10: Appsflyer | T10: Adjust | AF10: Branch
H11: Nilai | T11: Nilai | AF11: Nilai
H12: C | J12: A | L12: F | N12: E | P12: % Nilai Bobot | Q12: Nilai Bobot | T12: C | V12: A | X12: F | Z12: E | AB12: % Nilai Bobot | AC12: Nilai Bobot | AF12: C | AH12: A | AJ12: F | AL12: E | AN12: % Nilai Bobot | AO12: Nilai Bobot
H13: Bobot | I13: Raw Score | J13: Bobot | K13: Raw Score | L13: Bobot | M13: Raw Score | N13: Bobot | O13: Raw Score | Q13: (Nilai Penuh = Tingkat Kebutuhan) | T13: Bobot | U13: Raw Score | V13: Bobot | W13: Raw Score | X13: Bobot | Y13: Raw Score | Z13: Bobot | AA13: Raw Score | AC13: (Nilai Penuh = Tingkat Kebutuhan) | AF13: Bobot | AG13: Raw Score | AH13: Bobot | AI13: Raw Score | AJ13: Bobot | AK13: Raw Score | AL13: Bobot | AM13: Raw Score | AO13: (Nilai Penuh = Tingkat Kebutuhan)
I14: Max | K14: Max | M14: Max | O14: Max | U14: Max | W14: Max | Y14: Max | AA14: Max | AG14: Max | AI14: Max | AK14: Max | AM14: Max
I15: 3 | K15: 1 | M15: 3 | O15: 3 | U15: 3 | W15: 1 | Y15: 3 | AA15: 3 | AG15: 3 | AI15: 1 | AK15: 3 | AM15: 3
A16: 1 | B16: Attribution Tracking and In App Tracking | C16: Tracking | D16: 1. Click & Impression Attribution; and the ability to do multi touch attribution. 2. Ability to differentiate between organic and paid install. 3. Custom in application tracking based on what customers and potential customers do in the app | E16: 3 | H16: 0.25 | J16: 0.25 | L16: 0.25 | N16: 0.25 | P16: =((I16/$I$15)*H16+K16/$K$15*J16+M16/$M$15*L16+O16/$O$15*N16) -> 0 | Q16: =((I16/$I$15)*H16+K16/$K$15*J16+M16/$M$15*L16+O16/$O$15*N16)*$E16 -> 0 | T16: 0.25 | V16: 0.25 | X16: 0.25 | Z16: 0.25 | AB16: =((U16/$I$15)*T16+W16/$K$15*V16+Y16/$M$15*X16+AA16/$O$15*Z16) -> 0 | AC16: =((U16/$I$15)*T16+W16/$K$15*V16+Y16/$M$15*X16+AA16/$O$15*Z16)*$E16 -> 0 | AF16: 0.25 | AH16: 0.25 | AJ16: 0.25 | AL16: 0.25 | AN16: =((AG16/$I$15)*AF16+AI16/$K$15*AH16+AK16/$M$15*AJ16+AM16/$O$15*AL16) -> 0 | AO16: =((AG16/$I$15)*AF16+AI16/$K$15*AH16+AK16/$M$15*AJ16+AM16/$O$15*AL16)*$E16 -> 0
A17: 2 | B17: Uninstall and Inactive Tracking + re-attribution tracking | C17: Tracking | D17: 1. Identifying users who have uninstall the application or become inactive. 2. After a campaign can measure performance in regards to reverting customers (those who uninstall has install the aplication, those who are inactive has become active again) | E17: 3 | H17: 0.25 | J17: 0.25 | L17: 0.25 | N17: 0.25 | P17: =((I17/$I$15)*H17+K17/$K$15*J17+M17/$M$15*L17+O17/$O$15*N17) -> 0 | Q17: =((I17/$I$15)*H17+K17/$K$15*J17+M17/$M$15*L17+O17/$O$15*N17)*$E17 -> 0 | T17: 0.25 | V17: 0.25 | X17: 0.25 | Z17: 0.25 | AB17: =((U17/$I$15)*T17+W17/$K$15*V17+Y17/$M$15*X17+AA17/$O$15*Z17) -> 0 | AC17: =((U17/$I$15)*T17+W17/$K$15*V17+Y17/$M$15*X17+AA17/$O$15*Z17)*$E17 -> 0 | AF17: 0.25 | AH17: 0.25 | AJ17: 0.25 | AL17: 0.25 | AN17: =((AG17/$I$15)*AF17+AI17/$K$15*AH17+AK17/$M$15*AJ17+AM17/$O$15*AL17) -> 0 | AO17: =((AG17/$I$15)*AF17+AI17/$K$15*AH17+AK17/$M$15*AJ17+AM17/$O$15*AL17)*$E17 -> 0
A18: 3 | B18: App Tracking | C18: Tracking | D18: Ability to track multiple apps; number of apps that can be tracked | E18: 1 | H18: 0.3 | J18: 0.1 | L18: 0.5 | N18: 0.1 | P18: =((I18/$I$15)*H18+K18/$K$15*J18+M18/$M$15*L18+O18/$O$15*N18) -> 0 | Q18: =((I18/$I$15)*H18+K18/$K$15*J18+M18/$M$15*L18+O18/$O$15*N18)*$E18 -> 0 | T18: 0.3 | V18: 0.1 | X18: 0.5 | Z18: 0.1 | AB18: =((U18/$I$15)*T18+W18/$K$15*V18+Y18/$M$15*X18+AA18/$O$15*Z18) -> 0 | AC18: =((U18/$I$15)*T18+W18/$K$15*V18+Y18/$M$15*X18+AA18/$O$15*Z18)*$E18 -> 0 | AF18: 0.3 | AH18: 0.1 | AJ18: 0.5 | AL18: 0.1 | AN18: =((AG18/$I$15)*AF18+AI18/$K$15*AH18+AK18/$M$15*AJ18+AM18/$O$15*AL18) -> 0 | AO18: =((AG18/$I$15)*AF18+AI18/$K$15*AH18+AK18/$M$15*AJ18+AM18/$O$15*AL18)*$E18 -> 0
A19: Total Tracking | D19: Maximum Score: | E19: =SUM(E16:E18) -> 7 | H19: Nilai Bobot: | I19: =SUM(Q16:Q16) -> 0 | Q19: =I19/$E19 -> 0 | T19: Nilai Bobot: | U19: =SUM(AC16:AC16) -> 0 | AC19: =U19/$E19 -> 0 | AF19: Nilai Bobot: | AG19: =SUM(AO16:AO16) -> 0 | AO19: =AG19/$E19 -> 0
A20: 4 | B20: Audience Builder | C20: Segmentation | D20: Building audience based on customers need to do retargeting and reengagement in digital media platform | E20: 3 | H20: 0.25 | J20: 0.25 | L20: 0.25 | N20: 0.25 | P20: =((I20/$I$15)*H20+K20/$K$15*J20+M20/$M$15*L20+O20/$O$15*N20) -> 0 | Q20: =((I20/$I$15)*H20+K20/$K$15*J20+M20/$M$15*L20+O20/$O$15*N20)*$E20 -> 0 | T20: 0.25 | V20: 0.25 | X20: 0.25 | Z20: 0.25 | AB20: =((U20/$I$15)*T20+W20/$K$15*V20+Y20/$M$15*X20+AA20/$O$15*Z20) -> 0 | AC20: =((U20/$I$15)*T20+W20/$K$15*V20+Y20/$M$15*X20+AA20/$O$15*Z20)*$E20 -> 0 | AF20: 0.25 | AH20: 0.25 | AJ20: 0.25 | AL20: 0.25 | AN20: =((AG20/$I$15)*AF20+AI20/$K$15*AH20+AK20/$M$15*AJ20+AM20/$O$15*AL20) -> 0 | AO20: =((AG20/$I$15)*AF20+AI20/$K$15*AH20+AK20/$M$15*AJ20+AM20/$O$15*AL20)*$E20 -> 0
A21: 5 | B21: Fraud Prevention | C21: Detection Type | D21: Preventing and identifying fraud digital campaign performance | E21: 1 | H21: 0.25 | J21: 0.25 | L21: 0.25 | N21: 0.25 | P21: =((I21/$I$15)*H21+K21/$K$15*J21+M21/$M$15*L21+O21/$O$15*N21) -> 0 | Q21: =((I21/$I$15)*H21+K21/$K$15*J21+M21/$M$15*L21+O21/$O$15*N21)*$E21 -> 0 | T21: 0.25 | V21: 0.25 | X21: 0.25 | Z21: 0.25 | AB21: =((U21/$I$15)*T21+W21/$K$15*V21+Y21/$M$15*X21+AA21/$O$15*Z21) -> 0 | AC21: =((U21/$I$15)*T21+W21/$K$15*V21+Y21/$M$15*X21+AA21/$O$15*Z21)*$E21 -> 0 | AF21: 0.25 | AH21: 0.25 | AJ21: 0.25 | AL21: 0.25 | AN21: =((AG21/$I$15)*AF21+AI21/$K$15*AH21+AK21/$M$15*AJ21+AM21/$O$15*AL21) -> 0 | AO21: =((AG21/$I$15)*AF21+AI21/$K$15*AH21+AK21/$M$15*AJ21+AM21/$O$15*AL21)*$E21 -> 0
A22: Total Additional Feature | D22: Maximum Score: | E22: =SUM(E20:E21) -> 4 | H22: Nilai Bobot: | I22: =SUM(Q20:Q21) -> 0 | Q22: =I22/$E22 -> 0 | T22: Nilai Bobot: | U22: =SUM(AC20:AC21) -> 0 | AC22: =U22/$E22 -> 0 | AF22: Nilai Bobot: | AG22: =SUM(AO20:AO21) -> 0 | AO22: =AG22/$E22 -> 0
A23: 6 | B23: Real time Attribtion & Reporting + Customizable dashboard | C23: Reporting | D23: Dashboard able to show and report real time data. Dashboard can be customize by users based on need | E23: 3 | H23: 0.25 | J23: 0.25 | L23: 0.25 | N23: 0.25 | P23: =((I23/$I$15)*H23+K23/$K$15*J23+M23/$M$15*L23+O23/$O$15*N23) -> 0 | Q23: =((I23/$I$15)*H23+K23/$K$15*J23+M23/$M$15*L23+O23/$O$15*N23)*$E23 -> 0 | T23: 0.25 | V23: 0.25 | X23: 0.25 | Z23: 0.25 | AB23: =((U23/$I$15)*T23+W23/$K$15*V23+Y23/$M$15*X23+AA23/$O$15*Z23) -> 0 | AC23: =((U23/$I$15)*T23+W23/$K$15*V23+Y23/$M$15*X23+AA23/$O$15*Z23)*$E23 -> 0 | AF23: 0.25 | AH23: 0.25 | AJ23: 0.25 | AL23: 0.25 | AN23: =((AG23/$I$15)*AF23+AI23/$K$15*AH23+AK23/$M$15*AJ23+AM23/$O$15*AL23) -> 0 | AO23: =((AG23/$I$15)*AF23+AI23/$K$15*AH23+AK23/$M$15*AJ23+AM23/$O$15*AL23)*$E23 -> 0
A24: 7 | B24: Raw Data Accessand generating report | C24: Reporting | D24: Access and ability to download raw data. Ability to download variety of reports including charts, reports, CSV reports, ROI/RAS, cohort data by events and other type of reports | E24: 3 | H24: 0.25 | J24: 0.25 | L24: 0.25 | N24: 0.25 | P24: =((I24/$I$15)*H24+K24/$K$15*J24+M24/$M$15*L24+O24/$O$15*N24) -> 0 | T24: 0.25 | V24: 0.25 | X24: 0.25 | Z24: 0.25 | AB24: =((U24/$I$15)*T24+W24/$K$15*V24+Y24/$M$15*X24+AA24/$O$15*Z24) -> 0 | AF24: 0.25 | AH24: 0.25 | AJ24: 0.25 | AL24: 0.25 | AN24: =((AG24/$I$15)*AF24+AI24/$K$15*AH24+AK24/$M$15*AJ24+AM24/$O$15*AL24) -> 0
A25: 8 | B25: Access | C25: Access | D25: Number of people who can access the platform; the ability to determine the type of access each user have | E25: 2 | H25: 0.25 | J25: 0.25 | L25: 0.25 | N25: 0.25 | P25: =((I25/$I$15)*H25+K25/$K$15*J25+M25/$M$15*L25+O25/$O$15*N25) -> 0 | T25: 0.25 | V25: 0.25 | X25: 0.25 | Z25: 0.25 | AB25: =((U25/$I$15)*T25+W25/$K$15*V25+Y25/$M$15*X25+AA25/$O$15*Z25) -> 0 | AF25: 0.25 | AH25: 0.25 | AJ25: 0.25 | AL25: 0.25 | AN25: =((AG25/$I$15)*AF25+AI25/$K$15*AH25+AK25/$M$15*AJ25+AM25/$O$15*AL25) -> 0
A26: Total Reporting and Dashboard | D26: Maximum Score: | E26: =SUM(E23:E25) -> 8 | H26: Nilai Bobot: | I26: =SUM(Q23:Q23) -> 0 | Q26: =I26/$E26 -> 0 | T26: Nilai Bobot: | U26: =SUM(AC23:AC23) -> 0 | AC26: =U26/$E26 -> 0 | AF26: Nilai Bobot: | AG26: =SUM(AO23:AO23) -> 0 | AO26: =AG26/$E26 -> 0
A27: 9 | B27: Data Size | C27: SDK & Traffic Data Size | D27: SDK size implemented in our Apps and traffic data sent to Attribution platform must both be small enough to not affect our apps performance | E27: 3 | H27: 0.5 | I27: 3 | J27: 0.1 | K27: 1 | L27: 0.3 | M27: 2 | N27: =1-L27-J27-H27 -> 0.1 | O27: 2 | P27: =((I27/$I$15)*H27+K27/$K$15*J27+M27/$M$15*L27+O27/$O$15*N27) -> 0.86666667 | Q27: =((I27/$I$15)*H27+K27/$K$15*J27+M27/$M$15*L27+O27/$O$15*N27)*$E27 -> 2.6 | T27: 0.5 | U27: 3 | V27: 0.1 | W27: 0 | X27: 0.3 | Y27: 2 | Z27: =1-X27-V27-T27 -> 0.1 | AA27: 2 | AB27: =((U27/$I$15)*T27+W27/$K$15*V27+Y27/$M$15*X27+AA27/$O$15*Z27) -> 0.76666667 | AC27: =((U27/$I$15)*T27+W27/$K$15*V27+Y27/$M$15*X27+AA27/$O$15*Z27)*$E27 -> 2.3 | AF27: 0.5 | AG27: 0 | AH27: 0.1 | AI27: 0 | AJ27: 0.3 | AK27: 0 | AL27: =1-AJ27-AH27-AF27 -> 0.1 | AM27: 0 | AN27: =((AG27/$I$15)*AF27+AI27/$K$15*AH27+AK27/$M$15*AJ27+AM27/$O$15*AL27) -> 0 | AO27: =((AG27/$I$15)*AF27+AI27/$K$15*AH27+AK27/$M$15*AJ27+AM27/$O$15*AL27)*$E27 -> 0
A28: 10 | B28: Intergration | C28: Integration Method | D28: Easy to integrate to our Mobile Platform | E28: 3 | H28: 0.5 | I28: 3 | J28: 0.1 | K28: 1 | L28: 0.3 | M28: 2 | N28: =1-L28-J28-H28 -> 0.1 | O28: 2 | P28: =((I28/$I$15)*H28+K28/$K$15*J28+M28/$M$15*L28+O28/$O$15*N28) -> 0.86666667 | Q28: =((I28/$I$15)*H28+K28/$K$15*J28+M28/$M$15*L28+O28/$O$15*N28)*$E28 -> 2.6 | T28: 0.5 | U28: 1 | V28: 0.1 | W28: 1 | X28: 0.3 | Y28: 1 | Z28: =1-X28-V28-T28 -> 0.1 | AA28: 1 | AB28: =((U28/$I$15)*T28+W28/$K$15*V28+Y28/$M$15*X28+AA28/$O$15*Z28) -> 0.4 | AC28: =((U28/$I$15)*T28+W28/$K$15*V28+Y28/$M$15*X28+AA28/$O$15*Z28)*$E28 -> 1.2 | AF28: 0.5 | AG28: 0 | AH28: 0.1 | AI28: 0 | AJ28: 0.3 | AK28: 0 | AL28: =1-AJ28-AH28-AF28 -> 0.1 | AM28: 0 | AN28: =((AG28/$I$15)*AF28+AI28/$K$15*AH28+AK28/$M$15*AJ28+AM28/$O$15*AL28) -> 0 | AO28: =((AG28/$I$15)*AF28+AI28/$K$15*AH28+AK28/$M$15*AJ28+AM28/$O$15*AL28)*$E28 -> 0
A29: 11 | B29: Security | C29: Certification Related to Security / Pentest Report | D29: Vendor should have certification related to data security and atleast have Pentest report ( or doing pentest regularly to its platform) | E29: 3 | H29: 0.5 | I29: 3 | J29: 0.1 | K29: 1 | L29: 0.3 | M29: 3 | N29: =1-L29-J29-H29 -> 0.1 | O29: 3 | P29: =((I29/$I$15)*H29+K29/$K$15*J29+M29/$M$15*L29+O29/$O$15*N29) -> 1 | Q29: =((I29/$I$15)*H29+K29/$K$15*J29+M29/$M$15*L29+O29/$O$15*N29)*$E29 -> 3 | T29: 0.5 | U29: 0 | V29: 0.1 | W29: 0 | X29: 0.3 | Y29: 0 | Z29: =1-X29-V29-T29 -> 0.1 | AA29: 0 | AB29: =((U29/$I$15)*T29+W29/$K$15*V29+Y29/$M$15*X29+AA29/$O$15*Z29) -> 0 | AC29: =((U29/$I$15)*T29+W29/$K$15*V29+Y29/$M$15*X29+AA29/$O$15*Z29)*$E29 -> 0 | AF29: 0.5 | AG29: 0 | AH29: 0.1 | AI29: 0 | AJ29: 0.3 | AK29: 0 | AL29: =1-AJ29-AH29-AF29 -> 0.1 | AM29: 0 | AN29: =((AG29/$I$15)*AF29+AI29/$K$15*AH29+AK29/$M$15*AJ29+AM29/$O$15*AL29) -> 0 | AO29: =((AG29/$I$15)*AF29+AI29/$K$15*AH29+AK29/$M$15*AJ29+AM29/$O$15*AL29)*$E29 -> 0
A30: 12 | B30: Implementation | C30: Support Hybrid Platform based on Cordova | D30: The SDK should be able to run and fully integrated under hybrid platform based application such as cordova | E30: 3 | H30: 0.5 | I30: 3 | J30: 0.1 | K30: 1 | L30: 0.3 | M30: 1 | N30: =1-L30-J30-H30 -> 0.1 | O30: 1 | P30: =((I30/$I$15)*H30+K30/$K$15*J30+M30/$M$15*L30+O30/$O$15*N30) -> 0.73333333 | Q30: =((I30/$I$15)*H30+K30/$K$15*J30+M30/$M$15*L30+O30/$O$15*N30)*$E30 -> 2.2 | T30: 0.5 | U30: 0 | V30: 0.1 | W30: 0 | X30: 0.3 | Y30: 0 | Z30: =1-X30-V30-T30 -> 0.1 | AA30: 0 | AB30: =((U30/$I$15)*T30+W30/$K$15*V30+Y30/$M$15*X30+AA30/$O$15*Z30) -> 0 | AC30: =((U30/$I$15)*T30+W30/$K$15*V30+Y30/$M$15*X30+AA30/$O$15*Z30)*$E30 -> 0 | AF30: 0.5 | AG30: 0 | AH30: 0.1 | AI30: 0 | AJ30: 0.3 | AK30: 0 | AL30: =1-AJ30-AH30-AF30 -> 0.1 | AM30: 0 | AN30: =((AG30/$I$15)*AF30+AI30/$K$15*AH30+AK30/$M$15*AJ30+AM30/$O$15*AL30) -> 0 | AO30: =((AG30/$I$15)*AF30+AI30/$K$15*AH30+AK30/$M$15*AJ30+AM30/$O$15*AL30)*$E30 -> 0
A31: 13 | B31: Others | C31: Cloud Regulation Workaround (if any) | D31: Due to cloud usage restriction, please also provide the workaround plan for cloud usage restriction | E31: 1 | H31: 0.5 | I31: 3 | J31: 0.1 | K31: 0 | L31: 0.3 | M31: 0 | N31: =1-L31-J31-H31 -> 0.1 | O31: 0 | P31: =((I31/$I$15)*H31+K31/$K$15*J31+M31/$M$15*L31+O31/$O$15*N31) -> 0.5 | Q31: =((I31/$I$15)*H31+K31/$K$15*J31+M31/$M$15*L31+O31/$O$15*N31)*$E31 -> 0.5 | T31: 0.5 | U31: 0 | V31: 0.1 | W31: 0 | X31: 0.3 | Y31: 0 | Z31: =1-X31-V31-T31 -> 0.1 | AA31: 0 | AB31: =((U31/$I$15)*T31+W31/$K$15*V31+Y31/$M$15*X31+AA31/$O$15*Z31) -> 0 | AC31: =((U31/$I$15)*T31+W31/$K$15*V31+Y31/$M$15*X31+AA31/$O$15*Z31)*$E31 -> 0 | AF31: 0.5 | AG31: 0 | AH31: 0.1 | AI31: 0 | AJ31: 0.3 | AK31: 0 | AL31: =1-AJ31-AH31-AF31 -> 0.1 | AM31: 0 | AN31: =((AG31/$I$15)*AF31+AI31/$K$15*AH31+AK31/$M$15*AJ31+AM31/$O$15*AL31) -> 0 | AO31: =((AG31/$I$15)*AF31+AI31/$K$15*AH31+AK31/$M$15*AJ31+AM31/$O$15*AL31)*$E31 -> 0
A32: Total IT Security, Intergration and Implementation | D32: Maximum Score: | E32: =SUM(E27:E31) -> 13 | H32: Nilai Bobot: | I32: =SUM(Q27:Q27) -> 2.6 | Q32: =I32/$E32 -> 0.2 | T32: Nilai Bobot: | U32: =SUM(AC27:AC27) -> 2.3 | AC32: =U32/$E32 -> 0.17692308 | AF32: Nilai Bobot: | AG32: =SUM(AO27:AO27) -> 0 | AO32: =AG32/$E32 -> 0
A33: 14 | B33: Support | C33: Support | D33: 1) SLA of support in regards to questions and problems concerning the platform. 2) Training consistency and frequency. 3) Success Manager | E33: 3 | H33: 0.5 | I33: 0 | J33: 0.1 | K33: 0 | L33: 0.3 | M33: 0 | N33: =1-L33-J33-H33 -> 0.1 | O33: 0 | P33: =((I33/$I$15)*H33+K33/$K$15*J33+M33/$M$15*L33+O33/$O$15*N33) -> 0 | Q33: =((I33/$I$15)*H33+K33/$K$15*J33+M33/$M$15*L33+O33/$O$15*N33)*$E33 -> 0 | T33: 0.5 | U33: 0 | V33: 0.1 | W33: 0 | X33: 0.3 | Y33: 0 | Z33: =1-X33-V33-T33 -> 0.1 | AA33: 0 | AB33: =((U33/$I$15)*T33+W33/$K$15*V33+Y33/$M$15*X33+AA33/$O$15*Z33) -> 0 | AC33: =((U33/$I$15)*T33+W33/$K$15*V33+Y33/$M$15*X33+AA33/$O$15*Z33)*$E33 -> 0 | AF33: 0.5 | AG33: 0 | AH33: 0.1 | AI33: 0 | AJ33: 0.3 | AK33: 0 | AL33: =1-AJ33-AH33-AF33 -> 0.1 | AM33: 0 | AN33: =((AG33/$I$15)*AF33+AI33/$K$15*AH33+AK33/$M$15*AJ33+AM33/$O$15*AL33) -> 0 | AO33: =((AG33/$I$15)*AF33+AI33/$K$15*AH33+AK33/$M$15*AJ33+AM33/$O$15*AL33)*$E33 -> 0
A34: Total Support | D34: Maximum Score: | E34: =SUM(E30:E30) -> 3 | H34: Nilai Bobot: | I34: =SUM(Q29:Q29) -> 3 | Q34: =I34/$E34 -> 1 | T34: Nilai Bobot: | U34: =SUM(AC29:AC29) -> 0 | AC34: =U34/$E34 -> 0 | AF34: Nilai Bobot: | AG34: =SUM(AO29:AO29) -> 0 | AO34: =AG34/$E34 -> 0

Sheet Qualitative Eval
A1: ='Score Summary'!A1:B3 -> Pengembangan Liveness | D1: Versi : 1.0
D2: Nomor :
D3: Tanggal : 28 November 2019
A4: Qualitative Evaluation
A7: Vendor: | C7: Vendor 1: Q2 Vendor 2: IDstar Vendor 3: MIS
A8: Evaluator Name: | C8: 1. Vebi Verdiana 2. Melie Rosita
A9: Signature | C9: 1. 2.
A10: 1 | B10: 2 | C10: 3 | D10: 4 | E10: 5 | F10: 6 | G10: 7 | H10: 8 | I10: 9 | J10: 10 | K10: 11 | L10: 12 | M10: 13 | N10: 14
A11: Langkah | B11: Kategori Kegiatan | C11: Rincian | D11: Tingkat Kebutuhan | G11: Vendor 1 | L11: Vendor 2 | R11: Vendor 3
G12: Tingkat Kepuasan | I12: Nilai Bobot | L12: Tingkat Kepuasan | N12: Nilai Bobot | R12: Tingkat Kepuasan | T12: Nilai Bobot
G13: Min | H13: Max | L13: Min | M13: Max | R13: Min | S13: Max
G14: 0 | H14: 5 | L14: 0 | M14: 5 | R14: 0 | S14: 5
A15: 1 | B15: Tingkat Kesiapan | C15: 1. Bahan tambahan untuk staff POC, mis. Powerpoin yang menggambarkan konsep, banyak contoh dari transaksi bisnis, bagan tambahan, dsb. | D15: 2 | I15: =(G15/$H$14)*$D15 -> 0 | N15: =(L15/$H$14)*$D15 -> 0 | T15: =(R15/$H$14)*$D15 -> 0
A16: =A15+1 -> 2 | B16: Tingkat Kesiapan | C16: 2. Kelengkapan dalam persiapan/ setting lingkungan POC mis. Setup server | D16: 2 | I16: =(G16/$H$14)*$D16 -> 0 | N16: =(L16/$H$14)*$D16 -> 0 | T16: =(R16/$H$14)*$D16 -> 0
A17: =A16+1 -> 3 | B17: Tingkat Kesiapan | C17: 3. Presentasi yang disiapkan dengan baik saat walkthrough skenario | D17: 2 | I17: =(G17/$H$14)*$D17 -> 0 | N17: =(L17/$H$14)*$D17 -> 0 | T17: =(R17/$H$14)*$D17 -> 0
A18: =A17+1 -> 4 | B18: Profesionalitas Vendor | C18: 1. Pengelolaan waktu yang efektif - dapat menyelesaikan script dalam kerangka waktu yang diberikan | D18: 2 | I18: =(G18/$H$14)*$D18 -> 0 | N18: =(L18/$H$14)*$D18 -> 0 | T18: =(R18/$H$14)*$D18 -> 0
A19: =A18+1 -> 5 | B19: Profesionalitas Vendor | C19: 2. Pengaturan urutan pengujian - Skenario pengujian yang diberikan diatur berdasarkan sarsaran pengujian | D19: 2 | I19: =(G19/$H$14)*$D19 -> 0 | N19: =(L19/$H$14)*$D19 -> 0 | T19: =(R19/$H$14)*$D19 -> 0
A20: =A19+1 -> 6 | B20: Profesionalitas Vendor | C20: 3. Personil yang kompeten dan berpengalaman - tingkat pemahaman | D20: 2 | I20: =(G20/$H$14)*$D20 -> 0 | N20: =(L20/$H$14)*$D20 -> 0 | T20: =(R20/$H$14)*$D20 -> 0
A21: =A20+1 -> 7 | B21: Profesionalitas Vendor | C21: - Memberi penjelasan dengan baik | D21: 2 | I21: =(G21/$H$14)*$D21 -> 0 | N21: =(L21/$H$14)*$D21 -> 0 | T21: =(R21/$H$14)*$D21 -> 0
A22: =A21+1 -> 8 | B22: Profesionalitas Vendor | C22: - Menanggapi dengan benar dan akurat | D22: 2 | I22: =(G22/$H$14)*$D22 -> 0 | N22: =(L22/$H$14)*$D22 -> 0 | T22: =(R22/$H$14)*$D22 -> 0
A23: =A22+1 -> 9 | B23: Profesionalitas Vendor | C23: 4. Bantuan langsung - memandu user untuk memfasilitasi proses pengujian | D23: 2 | I23: =(G23/$H$14)*$D23 -> 0 | N23: =(L23/$H$14)*$D23 -> 0 | T23: =(R23/$H$14)*$D23 -> 0
A24: =A23+1 -> 10 | B24: Profesionalitas Vendor | C24: 5. Pengendalian emosi - menanggapi pertanyaan dengan cara yang profesional (mis. Sabar, dsb) | D24: 2 | I24: =(G24/$H$14)*$D24 -> 0 | N24: =(L24/$H$14)*$D24 -> 0 | T24: =(R24/$H$14)*$D24 -> 0
A25: =A24+1 -> 11 | B25: Nilai Tambah | C25: 1.Berbagi proses best practice melebihi target pengujian | D25: 2 | I25: =(G25/$H$14)*$D25 -> 0 | N25: =(L25/$H$14)*$D25 -> 0 | T25: =(R25/$H$14)*$D25 -> 0
A26: =A25+1 -> 12 | B26: Nilai Tambah | C26: 2 Memberi benchmark/ perbandingan terhadap standar industri (berbagi penglaman) mis. Waktu yang dibutuhkan untuk proses pembukaan rekening dari awal hingga akhir | D26: 2 | I26: =(G26/$H$14)*$D26 -> 0 | N26: =(L26/$H$14)*$D26 -> 0 | T26: =(R26/$H$14)*$D26 -> 0
A27: =A26+1 -> 13 | B27: Pemahaman Arsitektur | C27: 1. Konsep arsitektur aplikasi | D27: 2 | I27: =(G27/$H$14)*$D27 -> 0 | N27: =(L27/$H$14)*$D27 -> 0 | T27: =(R27/$H$14)*$D27 -> 0
... A35: =A34+1 -> 21 | B35: Pemahaman Infrastruktur | C35: 6. Kemampuan Virtualisasi | D35: 2 | I35: =(G35/$H$14)*$D35 -> 0 | N35: =(L35/$H$14)*$D35 -> 0 | T35: =(R35/$H$14)*$D35 -> 0

Sheet Legend
A1: <NAMA DOKUMEN> | C1: Versi :
C2: Nomor :
C3: Tanggal :
A4: Legend
A6: Tingkat Kebutuhan | B6: Deskripsi Tingkat Kebutuhan
A7: 0 | B7: Tidak dibutuhkan
A8: 1 | B8: Ingin dimiliki / Jika memungkinkan
A9: 2 | B9: Dibutuhkan
A10: 3 | B10: Penting / Kritikal
A12: Kunci | C12: Deskripsi | D12: Jangkauan Nilai | E12: Deskripsi Nilai
A13: C | B13: Completeness | C13: Kelengkapan dari sejumlah fungsionalitas yang didukung oleh produk/ layanan | D13: 0 | E13: Sangat terbatas atau tidak ada
D14: 1 | E14: jangkauan terbatas
D15: 2 | E15: jangkauan rata - rata
D16: 3 | E16: Jangkauan lebar dan kompetitif
A17: A | B17: Accuracy | C17: Ketepatan hasil dari sistem | D17: 0 | E17: Tidak akurat
D18: 1 | E18: Akurat
A19: F | B19: Flexibility | C19: Tingkat fleksibilitas sistem dan seberapa banyak dan seberapa mudah proses konfigurasi tanpa pemrograman bisa dilakukan untuk mendukung kebutuhan Bank di masa depan | D19: 0 | E19: Tidak fleksibel
D20: 1 | E20: Sedikit fleksibel dan// atau sangat sulit dikonfigurasi
D21: 2 | E21: Fleksibilitas rata - rata
D22: 3 | E22: Fleksibel dan mudah mudah dikonfigurasi
A23: E | B23: Ease of Use | C23: Tingkat kesederhanaan dan kemudahan penggunaan sistem | D23: 0 | E23: Sangat sulit digunakan, tidak praktis, dan hampir tidak berfungsi
D24: 1 | E24: Sulit digunakan
D25: 2 | E25: Secara umum mudah digunakan
D26: 3 | E26: Sangat mudah digunakan
A28: Tingkat Kepuasan | B28: Deskripsi Nilai
A29: 0 | B29: Tidak memiliki kapabilitas / Tugas tidak dilaksanakan
A30: 1 | B30: Sangat tidak puas
A31: 2 | B31: Tidak puas
A32: 3 | B32: Biasa
A33: 4 | B33: Puas
A34: 5 | B34: Sangat puas
